WARNING 2022-10-29 00:59:41,608 django.request Bad Request: /api/instance/
WARNING 2022-10-29 01:00:53,592 django.request Bad Request: /api/instance/
WARNING 2022-10-29 01:01:07,122 django.request Bad Request: /api/instance/
WARNING 2022-10-29 12:50:27,575 django.request Bad Request: /api/instance/6ac42a48-5926-4826-9d8c-3e3341882565/redisgraph/check-module-loaded/
WARNING 2022-10-29 13:18:46,420 django.request Bad Request: /api/instance/6ac42a48-5926-4826-9d8c-3e3341882565/redisgraph/check-module-loaded/
WARNING 2022-10-29 13:39:54,683 django.request Bad Request: /api/instance/6ac42a48-5926-4826-9d8c-3e3341882565/redisgraph/check-module-loaded/
WARNING 2022-10-29 13:40:04,277 django.request Bad Request: /api/instance/6ac42a48-5926-4826-9d8c-3e3341882565/redistimeseries/module-info/
ERROR 2022-10-29 13:40:05,079 redisinsight Unknown command error from redis instance:
Traceback (most recent call last):
  File "./redisinsight/utils/__init__.py", line 199, in _wrapped_view
  File "./redisinsight/core/views/decorators.py", line 21, in wrapped_view
  File "./redisinsight/redisai/views.py", line 40, in _wrapped_view
  File "./redisinsight/redisai/views.py", line 85, in models_view
  File "./redisinsight/redisai/services.py", line 181, in list_models
  File "./redisinsight/redisai/services.py", line 157, in _list_models
  File "/usr/local/lib/python3.10/site-packages/redis/client.py", line 901, in execute_command
    return self.parse_response(conn, command_name, **options)
  File "/usr/local/lib/python3.10/site-packages/redis/client.py", line 915, in parse_response
    response = connection.read_response()
  File "/usr/local/lib/python3.10/site-packages/redis/connection.py", line 756, in read_response
    raise response
redis.exceptions.ResponseError: unknown command `AI._MODELSCAN`, with args beginning with: 
ERROR 2022-10-29 13:40:05,084 redisinsight Unknown command error from redis instance:
Traceback (most recent call last):
  File "./redisinsight/utils/__init__.py", line 199, in _wrapped_view
  File "./redisinsight/core/views/decorators.py", line 21, in wrapped_view
  File "./redisinsight/redisai/views.py", line 40, in _wrapped_view
  File "./redisinsight/redisai/views.py", line 224, in scripts_view
  File "./redisinsight/redisai/services.py", line 206, in list_scripts
  File "./redisinsight/redisai/services.py", line 185, in _list_scripts
  File "/usr/local/lib/python3.10/site-packages/redis/client.py", line 901, in execute_command
    return self.parse_response(conn, command_name, **options)
  File "/usr/local/lib/python3.10/site-packages/redis/client.py", line 915, in parse_response
    response = connection.read_response()
  File "/usr/local/lib/python3.10/site-packages/redis/connection.py", line 756, in read_response
    raise response
redis.exceptions.ResponseError: unknown command `AI._SCRIPTSCAN`, with args beginning with: 
ERROR 2022-10-29 13:40:05,119 django.request Unknown Status Code: /api/instance/6ac42a48-5926-4826-9d8c-3e3341882565/redisai/models/
ERROR 2022-10-29 13:40:05,120 django.request Unknown Status Code: /api/instance/6ac42a48-5926-4826-9d8c-3e3341882565/redisai/scripts/
